Workbook

Sheet Инструкция
A1: ОТЧЁТ ПО КАЧЕСТВУ ДАННЫХ ───────────────────────── ЧТО ЭТО Результат очистки 4 исходных таблиц: Товары, Поставщики, Продажи, Клиенты. СТРУКТУРА • *_исходные — сырые данные • *_очищенные — после нормализации • Справочники — категории, единицы, статусы • Итоговый_отчет — сводка и графики ГЛАВНЫЕ НАХОДКИ • 130 клиентов с некорректным email • 16 поставщиков с неправильным ИНН • 3 товара с розницей ниже закупки КАК ОБНОВИТЬ Данные тянутся формулами из *_исходные. Итоговый_отчет пересчитывается автоматически. Остались вопросы? Пишите: https://t.me/niyaz_gimadiev

Sheet Товары_исходные
A1: Артикул | B1: Наименование | C1: Категория | D1: Производитель | E1: Цена_закупки | F1: Цена_розница | G1: Единица_измерения
A2: №АРТ-001/24 | B2: Смартфон Apple iPhone 15 | C2: Смартфоны | D2: Apple | E2: 45 000,50 | F2: 79 990,00 | G2: шт
A3: АРТ_002 | B3: смартфон APPLE IPHONE 15 | C3: Телефоны | D3: Apple | E3: 44 500,00 | F3: 78 500,00 | G3: штука
A4: 003/24 | B4: Смартфон Apple iPhone 15 (Черный) | C4: Мобильные телефоны | D4: APPLE | E4: 43 800,00 | F4: 77 700 | G4: штуки
A5: №АРТ-004 | B5: Ноутбук ASUS ROG Zephyrus | C5: Ноутбуки | D5: ASUS | E5: 85 000 | F5: 129 999.99 | G5: шт.
A6: АРТ_005 | B6: ноутбук ASUS ROG Zephyrus | C6: Лэптопы | D6: asus | E6: 84 500,50 | F6: 128 500,00 | G6: шт
A7: 006-24 | B7: Ноутбук ASUS ROG Zephyrus (G14) | C7: Ноутбуки | D7: ASUS | E7: 86 000 | F7: 131 000 | G7: штука
A8: №АРТ-007 | B8: Смартфон Samsung Galaxy S24 | C8: Смартфоны | D8: Samsung | E8: 39 999,99 | F8: 69 999,00 | G8: шт.
A9: АРТ_008 | B9: смартфон SAMSUNG GALAXY S24 | C9: Телефоны | D9: SAMSUNG | E9: 39 500 | F9: 68 900 | G9: штуки
A10: 009/24 | B10: Смартфон Samsung Galaxy S24 (Синий) | C10: Мобильные телефоны | D10: Samsung | E10: 40 200 | F10: 70 500 | G10: шт
A11: №АРТ-010 | B11: Планшет iPad Pro 12.9 | C11: Планшеты | D11: Apple | E11: 55 000 | F11: 89 900 | G11: шт.
A12: АРТ_011 | B12: планшет APPLE IPAD PRO 12.9 | C12: Планшеты | D12: apple | E12: 54 500 | F12: 88 500 | G12: штука
... A502: 501/24 | B502: Клавиатура Logitech POP Keys (Pink) | C502: Аксессуары | D502: LOGITECH | E502: 4 000 | F502: 6 800 | G502: шт

Sheet Товары_очищенные
A1: Артикул | B1: Наименование | C1: Категория | D1: Производитель | E1: Цена_закупки | F1: Цена_розница | G1: Единица_измерения | H1: Проверка_цены | I1: Проверка_уникальности
A2: ="АРТ-"&LEFT(SUBSTITUTE(SUBSTITUTE(SUBSTITUTE(SUBSTITUTE('Товары_исходные'!A2,"№",""),"АРТ-",""),"АРТ_",""),"/","-"),3) -> АРТ-001 | B2: =PROPER(TRIM(IFERROR(LEFT('Товары_исходные'!B2,FIND("(",'Товары_исходные'!B2)-1),'Товары_исходные'!B2))) -> Смартфон Apple Iphone 15 | C2: =IFERROR(VLOOKUP('Товары_исходные'!C2,Справочники!$A$2:$B$50,2,FALSE),'Товары_исходные'!C2) -> Смартфоны | D2: =PROPER(TRIM('Товары_исходные'!D2)) -> Apple | E2: =IFERROR(VALUE(IF(AND(ISNUMBER(FIND(",",'Товары_исходные'!E2)),ISNUMBER(FIND(".",'Товары_исходные'!E2))),SUBSTITUTE(SUBSTITUTE(SUBSTITUTE(SUBSTITUTE('Товары_исходные'!E2," ",""),"руб.",""),"руб",""),",",""),SUBSTITUTE(SUBSTITUTE(SUBSTITUTE(SUBSTITUTE('Товары_исходные'!E2," ",""),"руб.",""),"руб",""),",","."))),0) -> 45000.5 | F2: =IFERROR(VALUE(IF(AND(ISNUMBER(FIND(",",'Товары_исходные'!F2)),ISNUMBER(FIND(".",'Товары_исходные'!F2))),SUBSTITUTE(SUBSTITUTE(SUBSTITUTE(SUBSTITUTE('Товары_исходные'!F2," ",""),"руб.",""),"руб",""),",",""),SUBSTITUTE(SUBSTITUTE(SUBSTITUTE(SUBSTITUTE('Товары_исходные'!F2," ",""),"руб.",""),"руб",""),",","."))),0) -> 79990 | G2: =IFERROR(VLOOKUP('Товары_исходные'!G2,Справочники!$D$2:$E$50,2,FALSE),"шт.") -> шт. | H2: =IF(F2>=E2,"OK","Розница ниже закупки") -> OK | I2: =IF(COUNTIF($A$2:$A$502,A2)=1,"OK","Дубликат") -> OK
A3: ="АРТ-"&LEFT(SUBSTITUTE(SUBSTITUTE(SUBSTITUTE(SUBSTITUTE(Товары_исходные!A3,"№",""),"АРТ-",""),"АРТ_",""),"/","-"),3) -> АРТ-002 | B3: =PROPER(TRIM(IFERROR(LEFT(Товары_исходные!B3,FIND("(",Товары_исходные!B3)-1),Товары_исходные!B3))) -> Смартфон Apple Iphone 15 | C3: =IFERROR(VLOOKUP(Товары_исходные!C3,Справочники!$A$2:$B$50,2,FALSE),Товары_исходные!C3) -> Смартфоны | D3: =PROPER(TRIM(Товары_исходные!D3)) -> Apple | E3: =IFERROR(VALUE(IF(AND(ISNUMBER(FIND(",",Товары_исходные!E3)),ISNUMBER(FIND(".",Товары_исходные!E3))),SUBSTITUTE(SUBSTITUTE(SUBSTITUTE(SUBSTITUTE(Товары_исходные!E3," ",""),"руб.",""),"руб",""),",",""),SUBSTITUTE(SUBSTITUTE(SUBSTITUTE(SUBSTITUTE(Товары_исходные!E3," ",""),"руб.",""),"руб",""),",","."))),0) -> 44500 | F3: =IFERROR(VALUE(IF(AND(ISNUMBER(FIND(",",Товары_исходные!F3)),ISNUMBER(FIND(".",Товары_исходные!F3))),SUBSTITUTE(SUBSTITUTE(SUBSTITUTE(SUBSTITUTE(Товары_исходные!F3," ",""),"руб.",""),"руб",""),",",""),SUBSTITUTE(SUBSTITUTE(SUBSTITUTE(SUBSTITUTE(Товары_исходные!F3," ",""),"руб.",""),"руб",""),",","."))),0) -> 78500 | G3: =IFERROR(VLOOKUP(Товары_исходные!G3,Справочники!$D$2:$E$50,2,FALSE),"шт.") -> шт. | H3: =IF(F3>=E3,"OK","Розница ниже закупки") -> OK | I3: =IF(COUNTIF($A$2:$A$502,A3)=1,"OK","Дубликат") -> OK
A4: ="АРТ-"&LEFT(SUBSTITUTE(SUBSTITUTE(SUBSTITUTE(SUBSTITUTE(Товары_исходные!A4,"№",""),"АРТ-",""),"АРТ_",""),"/","-"),3) -> АРТ-003 | B4: =PROPER(TRIM(IFERROR(LEFT(Товары_исходные!B4,FIND("(",Товары_исходные!B4)-1),Товары_исходные!B4))) -> Смартфон Apple Iphone 15 | C4: =IFERROR(VLOOKUP(Товары_исходные!C4,Справочники!$A$2:$B$50,2,FALSE),Товары_исходные!C4) -> Смартфоны | D4: =PROPER(TRIM(Товары_исходные!D4)) -> Apple | E4: =IFERROR(VALUE(IF(AND(ISNUMBER(FIND(",",Товары_исходные!E4)),ISNUMBER(FIND(".",Товары_исходные!E4))),SUBSTITUTE(SUBSTITUTE(SUBSTITUTE(SUBSTITUTE(Товары_исходные!E4," ",""),"руб.",""),"руб",""),",",""),SUBSTITUTE(SUBSTITUTE(SUBSTITUTE(SUBSTITUTE(Товары_исходные!E4," ",""),"руб.",""),"руб",""),",","."))),0) -> 43800 | F4: =IFERROR(VALUE(IF(AND(ISNUMBER(FIND(",",Товары_исходные!F4)),ISNUMBER(FIND(".",Товары_исходные!F4))),SUBSTITUTE(SUBSTITUTE(SUBSTITUTE(SUBSTITUTE(Товары_исходные!F4," ",""),"руб.",""),"руб",""),",",""),SUBSTITUTE(SUBSTITUTE(SUBSTITUTE(SUBSTITUTE(Товары_исходные!F4," ",""),"руб.",""),"руб",""),",","."))),0) -> 77700 | G4: =IFERROR(VLOOKUP(Товары_исходные!G4,Справочники!$D$2:$E$50,2,FALSE),"шт.") -> шт. | H4: =IF(F4>=E4,"OK","Розница ниже закупки") -> OK | I4: =IF(COUNTIF($A$2:$A$502,A4)=1,"OK","Дубликат") -> OK
A5: ="АРТ-"&LEFT(SUBSTITUTE(SUBSTITUTE(SUBSTITUTE(SUBSTITUTE(Товары_исходные!A5,"№",""),"АРТ-",""),"АРТ_",""),"/","-"),3) -> АРТ-004 | B5: =PROPER(TRIM(IFERROR(LEFT(Товары_исходные!B5,FIND("(",Товары_исходные!B5)-1),Товары_исходные!B5))) -> Ноутбук Asus Rog Zephyrus | C5: =IFERROR(VLOOKUP(Товары_исходные!C5,Справочники!$A$2:$B$50,2,FALSE),Товары_исходные!C5) -> Ноутбуки | D5: =PROPER(TRIM(Товары_исходные!D5)) -> Asus | E5: =IFERROR(VALUE(IF(AND(ISNUMBER(FIND(",",Товары_исходные!E5)),ISNUMBER(FIND(".",Товары_исходные!E5))),SUBSTITUTE(SUBSTITUTE(SUBSTITUTE(SUBSTITUTE(Товары_исходные!E5," ",""),"руб.",""),"руб",""),",",""),SUBSTITUTE(SUBSTITUTE(SUBSTITUTE(SUBSTITUTE(Товары_исходные!E5," ",""),"руб.",""),"руб",""),",","."))),0) -> 85000 | F5: =IFERROR(VALUE(IF(AND(ISNUMBER(FIND(",",Товары_исходные!F5)),ISNUMBER(FIND(".",Товары_исходные!F5))),SUBSTITUTE(SUBSTITUTE(SUBSTITUTE(SUBSTITUTE(Товары_исходные!F5," ",""),"руб.",""),"руб",""),",",""),SUBSTITUTE(SUBSTITUTE(SUBSTITUTE(SUBSTITUTE(Товары_исходные!F5," ",""),"руб.",""),"руб",""),",","."))),0) -> 129999.99 | G5: =IFERROR(VLOOKUP(Товары_исходные!G5,Справочники!$D$2:$E$50,2,FALSE),"шт.") -> шт. | H5: =IF(F5>=E5,"OK","Розница ниже закупки") -> OK | I5: =IF(COUNTIF($A$2:$A$502,A5)=1,"OK","Дубликат") -> OK
A6: ="АРТ-"&LEFT(SUBSTITUTE(SUBSTITUTE(SUBSTITUTE(SUBSTITUTE(Товары_исходные!A6,"№",""),"АРТ-",""),"АРТ_",""),"/","-"),3) -> АРТ-005 | B6: =PROPER(TRIM(IFERROR(LEFT(Товары_исходные!B6,FIND("(",Товары_исходные!B6)-1),Товары_исходные!B6))) -> Ноутбук Asus Rog Zephyrus | C6: =IFERROR(VLOOKUP(Товары_исходные!C6,Справочники!$A$2:$B$50,2,FALSE),Товары_исходные!C6) -> Ноутбуки | D6: =PROPER(TRIM(Товары_исходные!D6)) -> Asus | E6: =IFERROR(VALUE(IF(AND(ISNUMBER(FIND(",",Товары_исходные!E6)),ISNUMBER(FIND(".",Товары_исходные!E6))),SUBSTITUTE(SUBSTITUTE(SUBSTITUTE(SUBSTITUTE(Товары_исходные!E6," ",""),"руб.",""),"руб",""),",",""),SUBSTITUTE(SUBSTITUTE(SUBSTITUTE(SUBSTITUTE(Товары_исходные!E6," ",""),"руб.",""),"руб",""),",","."))),0) -> 84500.5 | F6: =IFERROR(VALUE(IF(AND(ISNUMBER(FIND(",",Товары_исходные!F6)),ISNUMBER(FIND(".",Товары_исходные!F6))),SUBSTITUTE(SUBSTITUTE(SUBSTITUTE(SUBSTITUTE(Товары_исходные!F6," ",""),"руб.",""),"руб",""),",",""),SUBSTITUTE(SUBSTITUTE(SUBSTITUTE(SUBSTITUTE(Товары_исходные!F6," ",""),"руб.",""),"руб",""),",","."))),0) -> 128500 | G6: =IFERROR(VLOOKUP(Товары_исходные!G6,Справочники!$D$2:$E$50,2,FALSE),"шт.") -> шт. | H6: =IF(F6>=E6,"OK","Розница ниже закупки") -> OK | I6: =IF(COUNTIF($A$2:$A$502,A6)=1,"OK","Дубликат") -> OK
A7: ="АРТ-"&LEFT(SUBSTITUTE(SUBSTITUTE(SUBSTITUTE(SUBSTITUTE(Товары_исходные!A7,"№",""),"АРТ-",""),"АРТ_",""),"/","-"),3) -> АРТ-006 | B7: =PROPER(TRIM(IFERROR(LEFT(Товары_исходные!B7,FIND("(",Товары_исходные!B7)-1),Товары_исходные!B7))) -> Ноутбук Asus Rog Zephyrus | C7: =IFERROR(VLOOKUP(Товары_исходные!C7,Справочники!$A$2:$B$50,2,FALSE),Товары_исходные!C7) -> Ноутбуки | D7: =PROPER(TRIM(Товары_исходные!D7)) -> Asus | E7: =IFERROR(VALUE(IF(AND(ISNUMBER(FIND(",",Товары_исходные!E7)),ISNUMBER(FIND(".",Товары_исходные!E7))),SUBSTITUTE(SUBSTITUTE(SUBSTITUTE(SUBSTITUTE(Товары_исходные!E7," ",""),"руб.",""),"руб",""),",",""),SUBSTITUTE(SUBSTITUTE(SUBSTITUTE(SUBSTITUTE(Товары_исходные!E7," ",""),"руб.",""),"руб",""),",","."))),0) -> 86000 | F7: =IFERROR(VALUE(IF(AND(ISNUMBER(FIND(",",Товары_исходные!F7)),ISNUMBER(FIND(".",Товары_исходные!F7))),SUBSTITUTE(SUBSTITUTE(SUBSTITUTE(SUBSTITUTE(Товары_исходные!F7," ",""),"руб.",""),"руб",""),",",""),SUBSTITUTE(SUBSTITUTE(SUBSTITUTE(SUBSTITUTE(Товары_исходные!F7," ",""),"руб.",""),"руб",""),",","."))),0) -> 131000 | G7: =IFERROR(VLOOKUP(Товары_исходные!G7,Справочники!$D$2:$E$50,2,FALSE),"шт.") -> шт. | H7: =IF(F7>=E7,"OK","Розница ниже закупки") -> OK | I7: =IF(COUNTIF($A$2:$A$502,A7)=1,"OK","Дубликат") -> OK
A8: ="АРТ-"&LEFT(SUBSTITUTE(SUBSTITUTE(SUBSTITUTE(SUBSTITUTE(Товары_исходные!A8,"№",""),"АРТ-",""),"АРТ_",""),"/","-"),3) -> АРТ-007 | B8: =PROPER(TRIM(IFERROR(LEFT(Товары_исходные!B8,FIND("(",Товары_исходные!B8)-1),Товары_исходные!B8))) -> Смартфон Samsung Galaxy S24 | C8: =IFERROR(VLOOKUP(Товары_исходные!C8,Справочники!$A$2:$B$50,2,FALSE),Товары_исходные!C8) -> Смартфоны | D8: =PROPER(TRIM(Товары_исходные!D8)) -> Samsung | E8: =IFERROR(VALUE(IF(AND(ISNUMBER(FIND(",",Товары_исходные!E8)),ISNUMBER(FIND(".",Товары_исходные!E8))),SUBSTITUTE(SUBSTITUTE(SUBSTITUTE(SUBSTITUTE(Товары_исходные!E8," ",""),"руб.",""),"руб",""),",",""),SUBSTITUTE(SUBSTITUTE(SUBSTITUTE(SUBSTITUTE(Товары_исходные!E8," ",""),"руб.",""),"руб",""),",","."))),0) -> 39999.99 | F8: =IFERROR(VALUE(IF(AND(ISNUMBER(FIND(",",Товары_исходные!F8)),ISNUMBER(FIND(".",Товары_исходные!F8))),SUBSTITUTE(SUBSTITUTE(SUBSTITUTE(SUBSTITUTE(Товары_исходные!F8," ",""),"руб.",""),"руб",""),",",""),SUBSTITUTE(SUBSTITUTE(SUBSTITUTE(SUBSTITUTE(Товары_исходные!F8," ",""),"руб.",""),"руб",""),",","."))),0) -> 69999 | G8: =IFERROR(VLOOKUP(Товары_исходные!G8,Справочники!$D$2:$E$50,2,FALSE),"шт.") -> шт. | H8: =IF(F8>=E8,"OK","Розница ниже закупки") -> OK | I8: =IF(COUNTIF($A$2:$A$502,A8)=1,"OK","Дубликат") -> OK
A9: ="АРТ-"&LEFT(SUBSTITUTE(SUBSTITUTE(SUBSTITUTE(SUBSTITUTE(Товары_исходные!A9,"№",""),"АРТ-",""),"АРТ_",""),"/","-"),3) -> АРТ-008 | B9: =PROPER(TRIM(IFERROR(LEFT(Товары_исходные!B9,FIND("(",Товары_исходные!B9)-1),Товары_исходные!B9))) -> Смартфон Samsung Galaxy S24 | C9: =IFERROR(VLOOKUP(Товары_исходные!C9,Справочники!$A$2:$B$50,2,FALSE),Товары_исходные!C9) -> Смартфоны | D9: =PROPER(TRIM(Товары_исходные!D9)) -> Samsung | E9: =IFERROR(VALUE(IF(AND(ISNUMBER(FIND(",",Товары_исходные!E9)),ISNUMBER(FIND(".",Товары_исходные!E9))),SUBSTITUTE(SUBSTITUTE(SUBSTITUTE(SUBSTITUTE(Товары_исходные!E9," ",""),"руб.",""),"руб",""),",",""),SUBSTITUTE(SUBSTITUTE(SUBSTITUTE(SUBSTITUTE(Товары_исходные!E9," ",""),"руб.",""),"руб",""),",","."))),0) -> 39500 | F9: =IFERROR(VALUE(IF(AND(ISNUMBER(FIND(",",Товары_исходные!F9)),ISNUMBER(FIND(".",Товары_исходные!F9))),SUBSTITUTE(SUBSTITUTE(SUBSTITUTE(SUBSTITUTE(Товары_исходные!F9," ",""),"руб.",""),"руб",""),",",""),SUBSTITUTE(SUBSTITUTE(SUBSTITUTE(SUBSTITUTE(Товары_исходные!F9," ",""),"руб.",""),"руб",""),",","."))),0) -> 68900 | G9: =IFERROR(VLOOKUP(Товары_исходные!G9,Справочники!$D$2:$E$50,2,FALSE),"шт.") -> шт. | H9: =IF(F9>=E9,"OK","Розница ниже закупки") -> OK | I9: =IF(COUNTIF($A$2:$A$502,A9)=1,"OK","Дубликат") -> OK
A10: ="АРТ-"&LEFT(SUBSTITUTE(SUBSTITUTE(SUBSTITUTE(SUBSTITUTE('Товары_исходные'!A10,"№",""),"АРТ-",""),"АРТ_",""),"/","-"),3) -> АРТ-009 | B10: =PROPER(TRIM(IFERROR(LEFT('Товары_исходные'!B10,FIND("(",'Товары_исходные'!B10)-1),'Товары_исходные'!B10))) -> Смартфон Samsung Galaxy S24 | C10: =IFERROR(VLOOKUP('Товары_исходные'!C10,Справочники!$A$2:$B$50,2,FALSE),'Товары_исходные'!C10) -> Смартфоны | D10: =PROPER(TRIM('Товары_исходные'!D10)) -> Samsung | E10: =IFERROR(VALUE(IF(AND(ISNUMBER(FIND(",",'Товары_исходные'!E10)),ISNUMBER(FIND(".",'Товары_исходные'!E10))),SUBSTITUTE(SUBSTITUTE(SUBSTITUTE(SUBSTITUTE('Товары_исходные'!E10," ",""),"руб.",""),"руб",""),",",""),SUBSTITUTE(SUBSTITUTE(SUBSTITUTE(SUBSTITUTE('Товары_исходные'!E10," ",""),"руб.",""),"руб",""),",","."))),0) -> 40200 | F10: =IFERROR(VALUE(IF(AND(ISNUMBER(FIND(",",'Товары_исходные'!F10)),ISNUMBER(FIND(".",'Товары_исходные'!F10))),SUBSTITUTE(SUBSTITUTE(SUBSTITUTE(SUBSTITUTE('Товары_исходные'!F10," ",""),"руб.",""),"руб",""),",",""),SUBSTITUTE(SUBSTITUTE(SUBSTITUTE(SUBSTITUTE('Товары_исходные'!F10," ",""),"руб.",""),"руб",""),",","."))),0) -> 70500 | G10: =IFERROR(VLOOKUP('Товары_исходные'!G10,Справочники!$D$2:$E$50,2,FALSE),"шт.") -> шт. | H10: =IF(F10>=E10,"OK","Розница ниже закупки") -> OK | I10: =IF(COUNTIF($A$2:$A$502,A10)=1,"OK","Дубликат") -> OK
A11: ="АРТ-"&LEFT(SUBSTITUTE(SUBSTITUTE(SUBSTITUTE(SUBSTITUTE(Товары_исходные!A11,"№",""),"АРТ-",""),"АРТ_",""),"/","-"),3) -> АРТ-010 | B11: =PROPER(TRIM(IFERROR(LEFT(Товары_исходные!B11,FIND("(",Товары_исходные!B11)-1),Товары_исходные!B11))) -> Планшет Ipad Pro 12.9 | C11: =IFERROR(VLOOKUP(Товары_исходные!C11,Справочники!$A$2:$B$50,2,FALSE),Товары_исходные!C11) -> Планшеты | D11: =PROPER(TRIM(Товары_исходные!D11)) -> Apple | E11: =IFERROR(VALUE(IF(AND(ISNUMBER(FIND(",",Товары_исходные!E11)),ISNUMBER(FIND(".",Товары_исходные!E11))),SUBSTITUTE(SUBSTITUTE(SUBSTITUTE(SUBSTITUTE(Товары_исходные!E11," ",""),"руб.",""),"руб",""),",",""),SUBSTITUTE(SUBSTITUTE(SUBSTITUTE(SUBSTITUTE(Товары_исходные!E11," ",""),"руб.",""),"руб",""),",","."))),0) -> 55000 | F11: =IFERROR(VALUE(IF(AND(ISNUMBER(FIND(",",Товары_исходные!F11)),ISNUMBER(FIND(".",Товары_исходные!F11))),SUBSTITUTE(SUBSTITUTE(SUBSTITUTE(SUBSTITUTE(Товары_исходные!F11," ",""),"руб.",""),"руб",""),",",""),SUBSTITUTE(SUBSTITUTE(SUBSTITUTE(SUBSTITUTE(Товары_исходные!F11," ",""),"руб.",""),"руб",""),",","."))),0) -> 89900 | G11: =IFERROR(VLOOKUP(Товары_исходные!G11,Справочники!$D$2:$E$50,2,FALSE),"шт.") -> шт. | H11: =IF(F11>=E11,"OK","Розница ниже закупки") -> OK | I11: =IF(COUNTIF($A$2:$A$502,A11)=1,"OK","Дубликат") -> OK
A12: ="АРТ-"&LEFT(SUBSTITUTE(SUBSTITUTE(SUBSTITUTE(SUBSTITUTE(Товары_исходные!A12,"№",""),"АРТ-",""),"АРТ_",""),"/","-"),3) -> АРТ-011 | B12: =PROPER(TRIM(IFERROR(LEFT(Товары_исходные!B12,FIND("(",Товары_исходные!B12)-1),Товары_исходные!B12))) -> Планшет Apple Ipad Pro 12.9 | C12: =IFERROR(VLOOKUP(Товары_исходные!C12,Справочники!$A$2:$B$50,2,FALSE),Товары_исходные!C12) -> Планшеты | D12: =PROPER(TRIM(Товары_исходные!D12)) -> Apple | E12: =IFERROR(VALUE(IF(AND(ISNUMBER(FIND(",",Товары_исходные!E12)),ISNUMBER(FIND(".",Товары_исходные!E12))),SUBSTITUTE(SUBSTITUTE(SUBSTITUTE(SUBSTITUTE(Товары_исходные!E12," ",""),"руб.",""),"руб",""),",",""),SUBSTITUTE(SUBSTITUTE(SUBSTITUTE(SUBSTITUTE(Товары_исходные!E12," ",""),"руб.",""),"руб",""),",","."))),0) -> 54500 | F12: =IFERROR(VALUE(IF(AND(ISNUMBER(FIND(",",Товары_исходные!F12)),ISNUMBER(FIND(".",Товары_исходные!F12))),SUBSTITUTE(SUBSTITUTE(SUBSTITUTE(SUBSTITUTE(Товары_исходные!F12," ",""),"руб.",""),"руб",""),",",""),SUBSTITUTE(SUBSTITUTE(SUBSTITUTE(SUBSTITUTE(Товары_исходные!F12," ",""),"руб.",""),"руб",""),",","."))),0) -> 88500 | G12: =IFERROR(VLOOKUP(Товары_исходные!G12,Справочники!$D$2:$E$50,2,FALSE),"шт.") -> шт. | H12: =IF(F12>=E12,"OK","Розница ниже закупки") -> OK | I12: =IF(COUNTIF($A$2:$A$502,A12)=1,"OK","Дубликат") -> OK
A13: ="АРТ-"&LEFT(SUBSTITUTE(SUBSTITUTE(SUBSTITUTE(SUBSTITUTE(Товары_исходные!A13,"№",""),"АРТ-",""),"АРТ_",""),"/","-"),3) -> АРТ-012 | B13: =PROPER(TRIM(IFERROR(LEFT(Товары_исходные!B13,FIND("(",Товары_исходные!B13)-1),Товары_исходные!B13))) -> Планшет Apple Ipad Pro 12.9 | C13: =IFERROR(VLOOKUP(Товары_исходные!C13,Справочники!$A$2:$B$50,2,FALSE),Товары_исходные!C13) -> Планшеты | D13: =PROPER(TRIM(Товары_исходные!D13)) -> Apple | E13: =IFERROR(VALUE(IF(AND(ISNUMBER(FIND(",",Товары_исходные!E13)),ISNUMBER(FIND(".",Товары_исходные!E13))),SUBSTITUTE(SUBSTITUTE(SUBSTITUTE(SUBSTITUTE(Товары_исходные!E13," ",""),"руб.",""),"руб",""),",",""),SUBSTITUTE(SUBSTITUTE(SUBSTITUTE(SUBSTITUTE(Товары_исходные!E13," ",""),"руб.",""),"руб",""),",","."))),0) -> 56000 | F13: =IFERROR(VALUE(IF(AND(ISNUMBER(FIND(",",Товары_исходные!F13)),ISNUMBER(FIND(".",Товары_исходные!F13))),SUBSTITUTE(SUBSTITUTE(SUBSTITUTE(SUBSTITUTE(Товары_исходные!F13," ",""),"руб.",""),"руб",""),",",""),SUBSTITUTE(SUBSTITUTE(SUBSTITUTE(SUBSTITUTE(Товары_исходные!F13," ",""),"руб.",""),"руб",""),",","."))),0) -> 91000 | G13: =IFERROR(VLOOKUP(Товары_исходные!G13,Справочники!$D$2:$E$50,2,FALSE),"шт.") -> шт. | H13: =IF(F13>=E13,"OK","Розница ниже закупки") -> OK | I13: =IF(COUNTIF($A$2:$A$502,A13)=1,"OK","Дубликат") -> OK
A14: ="АРТ-"&LEFT(SUBSTITUTE(SUBSTITUTE(SUBSTITUTE(SUBSTITUTE(Товары_исходные!A14,"№",""),"АРТ-",""),"АРТ_",""),"/","-"),3) -> АРТ-013 | B14: =PROPER(TRIM(IFERROR(LEFT(Товары_исходные!B14,FIND("(",Товары_исходные!B14)-1),Товары_исходные!B14))) -> Телевизор Lg Oled65C3 | C14: =IFERROR(VLOOKUP(Товары_исходные!C14,Справочники!$A$2:$B$50,2,FALSE),Товары_исходные!C14) -> Телевизоры | D14: =PROPER(TRIM(Товары_исходные!D14)) -> Lg | E14: =IFERROR(VALUE(IF(AND(ISNUMBER(FIND(",",Товары_исходные!E14)),ISNUMBER(FIND(".",Товары_исходные!E14))),SUBSTITUTE(SUBSTITUTE(SUBSTITUTE(SUBSTITUTE(Товары_исходные!E14," ",""),"руб.",""),"руб",""),",",""),SUBSTITUTE(SUBSTITUTE(SUBSTITUTE(SUBSTITUTE(Товары_исходные!E14," ",""),"руб.",""),"руб",""),",","."))),0) -> 95000 | F14: =IFERROR(VALUE(IF(AND(ISNUMBER(FIND(",",Товары_исходные!F14)),ISNUMBER(FIND(".",Товары_исходные!F14))),SUBSTITUTE(SUBSTITUTE(SUBSTITUTE(SUBSTITUTE(Товары_исходные!F14," ",""),"руб.",""),"руб",""),",",""),SUBSTITUTE(SUBSTITUTE(SUBSTITUTE(SUBSTITUTE(Товары_исходные!F14," ",""),"руб.",""),"руб",""),",","."))),0) -> 149999 | G14: =IFERROR(VLOOKUP(Товары_исходные!G14,Справочники!$D$2:$E$50,2,FALSE),"шт.") -> шт. | H14: =IF(F14>=E14,"OK","Розница ниже закупки") -> OK | I14: =IF(COUNTIF($A$2:$A$502,A14)=1,"OK","Дубликат") -> OK
A15: ="АРТ-"&LEFT(SUBSTITUTE(SUBSTITUTE(SUBSTITUTE(SUBSTITUTE(Товары_исходные!A15,"№",""),"АРТ-",""),"АРТ_",""),"/","-"),3) -> АРТ-014 | B15: =PROPER(TRIM(IFERROR(LEFT(Товары_исходные!B15,FIND("(",Товары_исходные!B15)-1),Товары_исходные!B15))) -> Телевизор Lg Oled65C3 | C15: =IFERROR(VLOOKUP(Товары_исходные!C15,Справочники!$A$2:$B$50,2,FALSE),Товары_исходные!C15) -> Телевизоры | D15: =PROPER(TRIM(Товары_исходные!D15)) -> Lg | E15: =IFERROR(VALUE(IF(AND(ISNUMBER(FIND(",",Товары_исходные!E15)),ISNUMBER(FIND(".",Товары_исходные!E15))),SUBSTITUTE(SUBSTITUTE(SUBSTITUTE(SUBSTITUTE(Товары_исходные!E15," ",""),"руб.",""),"руб",""),",",""),SUBSTITUTE(SUBSTITUTE(SUBSTITUTE(SUBSTITUTE(Товары_исходные!E15," ",""),"руб.",""),"руб",""),",","."))),0) -> 93500 | F15: =IFERROR(VALUE(IF(AND(ISNUMBER(FIND(",",Товары_исходные!F15)),ISNUMBER(FIND(".",Товары_исходные!F15))),SUBSTITUTE(SUBSTITUTE(SUBSTITUTE(SUBSTITUTE(Товары_исходные!F15," ",""),"руб.",""),"руб",""),",",""),SUBSTITUTE(SUBSTITUTE(SUBSTITUTE(SUBSTITUTE(Товары_исходные!F15," ",""),"руб.",""),"руб",""),",","."))),0) -> 147500 | G15: =IFERROR(VLOOKUP(Товары_исходные!G15,Справочники!$D$2:$E$50,2,FALSE),"шт.") -> шт. | H15: =IF(F15>=E15,"OK","Розница ниже закупки") -> OK | I15: =IF(COUNTIF($A$2:$A$502,A15)=1,"OK","Дубликат") -> OK
A16: ="АРТ-"&LEFT(SUBSTITUTE(SUBSTITUTE(SUBSTITUTE(SUBSTITUTE(Товары_исходные!A16,"№",""),"АРТ-",""),"АРТ_",""),"/","-"),3) -> АРТ-015 | B16: =PROPER(TRIM(IFERROR(LEFT(Товары_исходные!B16,FIND("(",Товары_исходные!B16)-1),Товары_исходные!B16))) -> Телевизор Lg Oled65C3 | C16: =IFERROR(VLOOKUP(Товары_исходные!C16,Справочники!$A$2:$B$50,2,FALSE),Товары_исходные!C16) -> Телевизоры | D16: =PROPER(TRIM(Товары_исходные!D16)) -> Lg | E16: =IFERROR(VALUE(IF(AND(ISNUMBER(FIND(",",Товары_исходные!E16)),ISNUMBER(FIND(".",Товары_исходные!E16))),SUBSTITUTE(SUBSTITUTE(SUBSTITUTE(SUBSTITUTE(Товары_исходные!E16," ",""),"руб.",""),"руб",""),",",""),SUBSTITUTE(SUBSTITUTE(SUBSTITUTE(SUBSTITUTE(Товары_исходные!E16," ",""),"руб.",""),"руб",""),",","."))),0) -> 96500 | F16: =IFERROR(VALUE(IF(AND(ISNUMBER(FIND(",",Товары_исходные!F16)),ISNUMBER(FIND(".",Товары_исходные!F16))),SUBSTITUTE(SUBSTITUTE(SUBSTITUTE(SUBSTITUTE(Товары_исходные!F16," ",""),"руб.",""),"руб",""),",",""),SUBSTITUTE(SUBSTITUTE(SUBSTITUTE(SUBSTITUTE(Товары_исходные!F16," ",""),"руб.",""),"руб",""),",","."))),0) -> 151000 | G16: =IFERROR(VLOOKUP(Товары_исходные!G16,Справочники!$D$2:$E$50,2,FALSE),"шт.") -> шт. | H16: =IF(F16>=E16,"OK","Розница ниже закупки") -> OK | I16: =IF(COUNTIF($A$2:$A$502,A16)=1,"OK","Дубликат") -> OK
A17: ="АРТ-"&LEFT(SUBSTITUTE(SUBSTITUTE(SUBSTITUTE(SUBSTITUTE(Товары_исходные!A17,"№",""),"АРТ-",""),"АРТ_",""),"/","-"),3) -> АРТ-016 | B17: =PROPER(TRIM(IFERROR(LEFT(Товары_исходные!B17,FIND("(",Товары_исходные!B17)-1),Товары_исходные!B17))) -> Наушники Sony Wh-1000Xm5 | C17: =IFERROR(VLOOKUP(Товары_исходные!C17,Справочники!$A$2:$B$50,2,FALSE),Товары_исходные!C17) -> Наушники | D17: =PROPER(TRIM(Товары_исходные!D17)) -> Sony | E17: =IFERROR(VALUE(IF(AND(ISNUMBER(FIND(",",Товары_исходные!E17)),ISNUMBER(FIND(".",Товары_исходные!E17))),SUBSTITUTE(SUBSTITUTE(SUBSTITUTE(SUBSTITUTE(Товары_исходные!E17," ",""),"руб.",""),"руб",""),",",""),SUBSTITUTE(SUBSTITUTE(SUBSTITUTE(SUBSTITUTE(Товары_исходные!E17," ",""),"руб.",""),"руб",""),",","."))),0) -> 18000 | F17: =IFERROR(VALUE(IF(AND(ISNUMBER(FIND(",",Товары_исходные!F17)),ISNUMBER(FIND(".",Товары_исходные!F17))),SUBSTITUTE(SUBSTITUTE(SUBSTITUTE(SUBSTITUTE(Товары_исходные!F17," ",""),"руб.",""),"руб",""),",",""),SUBSTITUTE(SUBSTITUTE(SUBSTITUTE(SUBSTITUTE(Товары_исходные!F17," ",""),"руб.",""),"руб",""),",","."))),0) -> 29990 | G17: =IFERROR(VLOOKUP(Товары_исходные!G17,Справочники!$D$2:$E$50,2,FALSE),"шт.") -> шт. | H17: =IF(F17>=E17,"OK","Розница ниже закупки") -> OK | I17: =IF(COUNTIF($A$2:$A$502,A17)=1,"OK","Дубликат") -> OK
A18: ="АРТ-"&LEFT(SUBSTITUTE(SUBSTITUTE(SUBSTITUTE(SUBSTITUTE(Товары_исходные!A18,"№",""),"АРТ-",""),"АРТ_",""),"/","-"),3) -> АРТ-017 | B18: =PROPER(TRIM(IFERROR(LEFT(Товары_исходные!B18,FIND("(",Товары_исходные!B18)-1),Товары_исходные!B18))) -> Наушники Sony Wh-1000Xm5 | C18: =IFERROR(VLOOKUP(Товары_исходные!C18,Справочники!$A$2:$B$50,2,FALSE),Товары_исходные!C18) -> Наушники | D18: =PROPER(TRIM(Товары_исходные!D18)) -> Sony | E18: =IFERROR(VALUE(IF(AND(ISNUMBER(FIND(",",Товары_исходные!E18)),ISNUMBER(FIND(".",Товары_исходные!E18))),SUBSTITUTE(SUBSTITUTE(SUBSTITUTE(SUBSTITUTE(Товары_исходные!E18," ",""),"руб.",""),"руб",""),",",""),SUBSTITUTE(SUBSTITUTE(SUBSTITUTE(SUBSTITUTE(Товары_исходные!E18," ",""),"руб.",""),"руб",""),",","."))),0) -> 17500 | F18: =IFERROR(VALUE(IF(AND(ISNUMBER(FIND(",",Товары_исходные!F18)),ISNUMBER(FIND(".",Товары_исходные!F18))),SUBSTITUTE(SUBSTITUTE(SUBSTITUTE(SUBSTITUTE(Товары_исходные!F18," ",""),"руб.",""),"руб",""),",",""),SUBSTITUTE(SUBSTITUTE(SUBSTITUTE(SUBSTITUTE(Товары_исходные!F18," ",""),"руб.",""),"руб",""),",","."))),0) -> 28900 | G18: =IFERROR(VLOOKUP(Товары_исходные!G18,Справочники!$D$2:$E$50,2,FALSE),"шт.") -> шт. | H18: =IF(F18>=E18,"OK","Розница ниже закупки") -> OK | I18: =IF(COUNTIF($A$2:$A$502,A18)=1,"OK","Дубликат") -> OK
A19: ="АРТ-"&LEFT(SUBSTITUTE(SUBSTITUTE(SUBSTITUTE(SUBSTITUTE(Товары_исходные!A19,"№",""),"АРТ-",""),"АРТ_",""),"/","-"),3) -> АРТ-018 | B19: =PROPER(TRIM(IFERROR(LEFT(Товары_исходные!B19,FIND("(",Товары_исходные!B19)-1),Товары_исходные!B19))) -> Наушники Sony Wh-1000Xm5 | C19: =IFERROR(VLOOKUP(Товары_исходные!C19,Справочники!$A$2:$B$50,2,FALSE),Товары_исходные!C19) -> Наушники | D19: =PROPER(TRIM(Товары_исходные!D19)) -> Sony | E19: =IFERROR(VALUE(IF(AND(ISNUMBER(FIND(",",Товары_исходные!E19)),ISNUMBER(FIND(".",Товары_исходные!E19))),SUBSTITUTE(SUBSTITUTE(SUBSTITUTE(SUBSTITUTE(Товары_исходные!E19," ",""),"руб.",""),"руб",""),",",""),SUBSTITUTE(SUBSTITUTE(SUBSTITUTE(SUBSTITUTE(Товары_исходные!E19," ",""),"руб.",""),"руб",""),",","."))),0) -> 18500 | F19: =IFERROR(VALUE(IF(AND(ISNUMBER(FIND(",",Товары_исходные!F19)),ISNUMBER(FIND(".",Товары_исходные!F19))),SUBSTITUTE(SUBSTITUTE(SUBSTITUTE(SUBSTITUTE(Товары_исходные!F19," ",""),"руб.",""),"руб",""),",",""),SUBSTITUTE(SUBSTITUTE(SUBSTITUTE(SUBSTITUTE(Товары_исходные!F19," ",""),"руб.",""),"руб",""),",","."))),0) -> 30500 | G19: =IFERROR(VLOOKUP(Товары_исходные!G19,Справочники!$D$2:$E$50,2,FALSE),"шт.") -> шт. | H19: =IF(F19>=E19,"OK","Розница ниже закупки") -> OK | I19: =IF(COUNTIF($A$2:$A$502,A19)=1,"OK","Дубликат") -> OK
A20: ="АРТ-"&LEFT(SUBSTITUTE(SUBSTITUTE(SUBSTITUTE(SUBSTITUTE(Товары_исходные!A20,"№",""),"АРТ-",""),"АРТ_",""),"/","-"),3) -> АРТ-019 | B20: =PROPER(TRIM(IFERROR(LEFT(Товары_исходные!B20,FIND("(",Товары_исходные!B20)-1),Товары_исходные!B20))) -> Ноутбук Lenovo Thinkpad X1 | C20: =IFERROR(VLOOKUP(Товары_исходные!C20,Справочники!$A$2:$B$50,2,FALSE),Товары_исходные!C20) -> Ноутбуки | D20: =PROPER(TRIM(Товары_исходные!D20)) -> Lenovo | E20: =IFERROR(VALUE(IF(AND(ISNUMBER(FIND(",",Товары_исходные!E20)),ISNUMBER(FIND(".",Товары_исходные!E20))),SUBSTITUTE(SUBSTITUTE(SUBSTITUTE(SUBSTITUTE(Товары_исходные!E20," ",""),"руб.",""),"руб",""),",",""),SUBSTITUTE(SUBSTITUTE(SUBSTITUTE(SUBSTITUTE(Товары_исходные!E20," ",""),"руб.",""),"руб",""),",","."))),0) -> 90000 | F20: =IFERROR(VALUE(IF(AND(ISNUMBER(FIND(",",Товары_исходные!F20)),ISNUMBER(FIND(".",Товары_исходные!F20))),SUBSTITUTE(SUBSTITUTE(SUBSTITUTE(SUBSTITUTE(Товары_исходные!F20," ",""),"руб.",""),"руб",""),",",""),SUBSTITUTE(SUBSTITUTE(SUBSTITUTE(SUBSTITUTE(Товары_исходные!F20," ",""),"руб.",""),"руб",""),",","."))),0) -> 135000 | G20: =IFERROR(VLOOKUP(Товары_исходные!G20,Справочники!$D$2:$E$50,2,FALSE),"шт.") -> шт. | H20: =IF(F20>=E20,"OK","Розница ниже закупки") -> OK | I20: =IF(COUNTIF($A$2:$A$502,A20)=1,"OK","Дубликат") -> OK
A21: ="АРТ-"&LEFT(SUBSTITUTE(SUBSTITUTE(SUBSTITUTE(SUBSTITUTE(Товары_исходные!A21,"№",""),"АРТ-",""),"АРТ_",""),"/","-"),3) -> АРТ-020 | B21: =PROPER(TRIM(IFERROR(LEFT(Товары_исходные!B21,FIND("(",Товары_исходные!B21)-1),Товары_исходные!B21))) -> Ноутбук Lenovo Thinkpad X1 | C21: =IFERROR(VLOOKUP(Товары_исходные!C21,Справочники!$A$2:$B$50,2,FALSE),Товары_исходные!C21) -> Ноутбуки | D21: =PROPER(TRIM(Товары_исходные!D21)) -> Lenovo | E21: =IFERROR(VALUE(IF(AND(ISNUMBER(FIND(",",Товары_исходные!E21)),ISNUMBER(FIND(".",Товары_исходные!E21))),SUBSTITUTE(SUBSTITUTE(SUBSTITUTE(SUBSTITUTE(Товары_исходные!E21," ",""),"руб.",""),"руб",""),",",""),SUBSTITUTE(SUBSTITUTE(SUBSTITUTE(SUBSTITUTE(Товары_исходные!E21," ",""),"руб.",""),"руб",""),",","."))),0) -> 89000 | F21: =IFERROR(VALUE(IF(AND(ISNUMBER(FIND(",",Товары_исходные!F21)),ISNUMBER(FIND(".",Товары_исходные!F21))),SUBSTITUTE(SUBSTITUTE(SUBSTITUTE(SUBSTITUTE(Товары_исходные!F21," ",""),"руб.",""),"руб",""),",",""),SUBSTITUTE(SUBSTITUTE(SUBSTITUTE(SUBSTITUTE(Товары_исходные!F21," ",""),"руб.",""),"руб",""),",","."))),0) -> 133500 | G21: =IFERROR(VLOOKUP(Товары_исходные!G21,Справочники!$D$2:$E$50,2,FALSE),"шт.") -> шт. | H21: =IF(F21>=E21,"OK","Розница ниже закупки") -> OK | I21: =IF(COUNTIF($A$2:$A$502,A21)=1,"OK","Дубликат") -> OK
A22: ="АРТ-"&LEFT(SUBSTITUTE(SUBSTITUTE(SUBSTITUTE(SUBSTITUTE(Товары_исходные!A22,"№",""),"АРТ-",""),"АРТ_",""),"/","-"),3) -> АРТ-021 | B22: =PROPER(TRIM(IFERROR(LEFT(Товары_исходные!B22,FIND("(",Товары_исходные!B22)-1),Товары_исходные!B22))) -> Ноутбук Lenovo Thinkpad X1 | C22: =IFERROR(VLOOKUP(Товары_исходные!C22,Справочники!$A$2:$B$50,2,FALSE),Товары_исходные!C22) -> Ноутбуки | D22: =PROPER(TRIM(Товары_исходные!D22)) -> Lenovo | E22: =IFERROR(VALUE(IF(AND(ISNUMBER(FIND(",",Товары_исходные!E22)),ISNUMBER(FIND(".",Товары_исходные!E22))),SUBSTITUTE(SUBSTITUTE(SUBSTITUTE(SUBSTITUTE(Товары_исходные!E22," ",""),"руб.",""),"руб",""),",",""),SUBSTITUTE(SUBSTITUTE(SUBSTITUTE(SUBSTITUTE(Товары_исходные!E22," ",""),"руб.",""),"руб",""),",","."))),0) -> 91500 | F22: =IFERROR(VALUE(IF(AND(ISNUMBER(FIND(",",Товары_исходные!F22)),ISNUMBER(FIND(".",Товары_исходные!F22))),SUBSTITUTE(SUBSTITUTE(SUBSTITUTE(SUBSTITUTE(Товары_исходные!F22," ",""),"руб.",""),"руб",""),",",""),SUBSTITUTE(SUBSTITUTE(SUBSTITUTE(SUBSTITUTE(Товары_исходные!F22," ",""),"руб.",""),"руб",""),",","."))),0) -> 137000 | G22: =IFERROR(VLOOKUP(Товары_исходные!G22,Справочники!$D$2:$E$50,2,FALSE),"шт.") -> шт. | H22: =IF(F22>=E22,"OK","Розница ниже закупки") -> OK | I22: =IF(COUNTIF($A$2:$A$502,A22)=1,"OK","Дубликат") -> OK
... A99: ="АРТ-"&LEFT(SUBSTITUTE(SUBSTITUTE(SUBSTITUTE(SUBSTITUTE(Товары_исходные!A99,"№",""),"АРТ-",""),"АРТ_",""),"/","-"),3) -> АРТ-098 | B99: =PROPER(TRIM(IFERROR(LEFT(Товары_исходные!B99,FIND("(",Товары_исходные!B99)-1),Товары_исходные!B99))) -> Мышь Razer Deathadder V3 | C99: =IFERROR(VLOOKUP(Товары_исходные!C99,Справочники!$A$2:$B$50,2,FALSE),Товары_исходные!C99) -> Аксессуары | D99: =PROPER(TRIM(Товары_исходные!D99)) -> Razer | E99: =IFERROR(VALUE(IF(AND(ISNUMBER(FIND(",",Товары_исходные!E99)),ISNUMBER(FIND(".",Товары_исходные!E99))),SUBSTITUTE(SUBSTITUTE(SUBSTITUTE(SUBSTITUTE(Товары_исходные!E99," ",""),"руб.",""),"руб",""),",",""),SUBSTITUTE(SUBSTITUTE(SUBSTITUTE(SUBSTITUTE(Товары_исходные!E99," ",""),"руб.",""),"руб",""),",","."))),0) -> 3200 | F99: =IFERROR(VALUE(IF(AND(ISNUMBER(FIND(",",Товары_исходные!F99)),ISNUMBER(FIND(".",Товары_исходные!F99))),SUBSTITUTE(SUBSTITUTE(SUBSTITUTE(SUBSTITUTE(Товары_исходные!F99," ",""),"руб.",""),"руб",""),",",""),SUBSTITUTE(SUBSTITUTE(SUBSTITUTE(SUBSTITUTE(Товары_исходные!F99," ",""),"руб.",""),"руб",""),",","."))),0) -> 6500 | G99: =IFERROR(VLOOKUP(Товары_исходные!G99,Справочники!$D$2:$E$50,2,FALSE),"шт.") -> шт. | H99: =IF(F99>=E99,"OK","Розница ниже закупки") -> OK | I99: =IF(COUNTIF($A$2:$A$502,A99)=1,"OK","Дубликат") -> OK
A100: ="АРТ-"&LEFT(SUBSTITUTE(SUBSTITUTE(SUBSTITUTE(SUBSTITUTE('Товары_исходные'!A100,"№",""),"АРТ-",""),"АРТ_",""),"/","-"),3) -> АРТ-099 | B100: =PROPER(TRIM(IFERROR(LEFT('Товары_исходные'!B100,FIND("(",'Товары_исходные'!B100)-1),'Товары_исходные'!B100))) -> Мышь Razer Deathadder V3 | C100: =IFERROR(VLOOKUP('Товары_исходные'!C100,Справочники!$A$2:$B$50,2,FALSE),'Товары_исходные'!C100) -> Аксессуары | D100: =PROPER(TRIM('Товары_исходные'!D100)) -> Razer | E100: =IFERROR(VALUE(IF(AND(ISNUMBER(FIND(",",'Товары_исходные'!E100)),ISNUMBER(FIND(".",'Товары_исходные'!E100))),SUBSTITUTE(SUBSTITUTE(SUBSTITUTE(SUBSTITUTE('Товары_исходные'!E100," ",""),"руб.",""),"руб",""),",",""),SUBSTITUTE(SUBSTITUTE(SUBSTITUTE(SUBSTITUTE('Товары_исходные'!E100," ",""),"руб.",""),"руб",""),",","."))),0) -> 3800 | F100: =IFERROR(VALUE(IF(AND(ISNUMBER(FIND(",",'Товары_исходные'!F100)),ISNUMBER(FIND(".",'Товары_исходные'!F100))),SUBSTITUTE(SUBSTITUTE(SUBSTITUTE(SUBSTITUTE('Товары_исходные'!F100," ",""),"руб.",""),"руб",""),",",""),SUBSTITUTE(SUBSTITUTE(SUBSTITUTE(SUBSTITUTE('Товары_исходные'!F100," ",""),"руб.",""),"руб",""),",","."))),0) -> 7500 | G100: =IFERROR(VLOOKUP('Товары_исходные'!G100,Справочники!$D$2:$E$50,2,FALSE),"шт.") -> шт. | H100: =IF(F100>=E100,"OK","Розница ниже закупки") -> OK | I100: =IF(COUNTIF($A$2:$A$502,A100)=1,"OK","Дубликат") -> OK
A101: ="АРТ-"&LEFT(SUBSTITUTE(SUBSTITUTE(SUBSTITUTE(SUBSTITUTE(Товары_исходные!A101,"№",""),"АРТ-",""),"АРТ_",""),"/","-"),3) -> АРТ-100 | B101: =PROPER(TRIM(IFERROR(LEFT(Товары_исходные!B101,FIND("(",Товары_исходные!B101)-1),Товары_исходные!B101))) -> Планшет Apple Ipad Mini | C101: =IFERROR(VLOOKUP(Товары_исходные!C101,Справочники!$A$2:$B$50,2,FALSE),Товары_исходные!C101) -> Планшеты | D101: =PROPER(TRIM(Товары_исходные!D101)) -> Apple | E101: =IFERROR(VALUE(IF(AND(ISNUMBER(FIND(",",Товары_исходные!E101)),ISNUMBER(FIND(".",Товары_исходные!E101))),SUBSTITUTE(SUBSTITUTE(SUBSTITUTE(SUBSTITUTE(Товары_исходные!E101," ",""),"руб.",""),"руб",""),",",""),SUBSTITUTE(SUBSTITUTE(SUBSTITUTE(SUBSTITUTE(Товары_исходные!E101," ",""),"руб.",""),"руб",""),",","."))),0) -> 35000 | F101: =IFERROR(VALUE(IF(AND(ISNUMBER(FIND(",",Товары_исходные!F101)),ISNUMBER(FIND(".",Товары_исходные!F101))),SUBSTITUTE(SUBSTITUTE(SUBSTITUTE(SUBSTITUTE(Товары_исходные!F101," ",""),"руб.",""),"руб",""),",",""),SUBSTITUTE(SUBSTITUTE(SUBSTITUTE(SUBSTITUTE(Товары_исходные!F101," ",""),"руб.",""),"руб",""),",","."))),0) -> 56990 | G101: =IFERROR(VLOOKUP(Товары_исходные!G101,Справочники!$D$2:$E$50,2,FALSE),"шт.") -> шт. | H101: =IF(F101>=E101,"OK","Розница ниже закупки") -> OK | I101: =IF(COUNTIF($A$2:$A$502,A101)=1,"OK","Дубликат") -> OK
A102: ="АРТ-"&LEFT(SUBSTITUTE(SUBSTITUTE(SUBSTITUTE(SUBSTITUTE(Товары_исходные!A102,"№",""),"АРТ-",""),"АРТ_",""),"/","-"),3) -> АРТ-101 | B102: =PROPER(TRIM(IFERROR(LEFT(Товары_исходные!B102,FIND("(",Товары_исходные!B102)-1),Товары_исходные!B102))) -> Планшет Apple Ipad Mini | C102: =IFERROR(VLOOKUP(Товары_исходные!C102,Справочники!$A$2:$B$50,2,FALSE),Товары_исходные!C102) -> Планшеты | D102: =PROPER(TRIM(Товары_исходные!D102)) -> Apple | E102: =IFERROR(VALUE(IF(AND(ISNUMBER(FIND(",",Товары_исходные!E102)),ISNUMBER(FIND(".",Товары_исходные!E102))),SUBSTITUTE(SUBSTITUTE(SUBSTITUTE(SUBSTITUTE(Товары_исходные!E102," ",""),"руб.",""),"руб",""),",",""),SUBSTITUTE(SUBSTITUTE(SUBSTITUTE(SUBSTITUTE(Товары_исходные!E102," ",""),"руб.",""),"руб",""),",","."))),0) -> 34000 | F102: =IFERROR(VALUE(IF(AND(ISNUMBER(FIND(",",Товары_исходные!F102)),ISNUMBER(FIND(".",Товары_исходные!F102))),SUBSTITUTE(SUBSTITUTE(SUBSTITUTE(SUBSTITUTE(Товары_исходные!F102," ",""),"руб.",""),"руб",""),",",""),SUBSTITUTE(SUBSTITUTE(SUBSTITUTE(SUBSTITUTE(Товары_исходные!F102," ",""),"руб.",""),"руб",""),",","."))),0) -> 55500 | G102: =IFERROR(VLOOKUP(Товары_исходные!G102,Справочники!$D$2:$E$50,2,FALSE),"шт.") -> шт. | H102: =IF(F102>=E102,"OK","Розница ниже закупки") -> OK | I102: =IF(COUNTIF($A$2:$A$502,A102)=1,"OK","Дубликат") -> OK
A103: ="АРТ-"&LEFT(SUBSTITUTE(SUBSTITUTE(SUBSTITUTE(SUBSTITUTE(Товары_исходные!A103,"№",""),"АРТ-",""),"АРТ_",""),"/","-"),3) -> АРТ-102 | B103: =PROPER(TRIM(IFERROR(LEFT(Товары_исходные!B103,FIND("(",Товары_исходные!B103)-1),Товары_исходные!B103))) -> Планшет Apple Ipad Mini | C103: =IFERROR(VLOOKUP(Товары_исходные!C103,Справочники!$A$2:$B$50,2,FALSE),Товары_исходные!C103) -> Планшеты | D103: =PROPER(TRIM(Товары_исходные!D103)) -> Apple | E103: =IFERROR(VALUE(IF(AND(ISNUMBER(FIND(",",Товары_исходные!E103)),ISNUMBER(FIND(".",Товары_исходные!E103))),SUBSTITUTE(SUBSTITUTE(SUBSTITUTE(SUBSTITUTE(Товары_исходные!E103," ",""),"руб.",""),"руб",""),",",""),SUBSTITUTE(SUBSTITUTE(SUBSTITUTE(SUBSTITUTE(Товары_исходные!E103," ",""),"руб.",""),"руб",""),",","."))),0) -> 36000 | F103: =IFERROR(VALUE(IF(AND(ISNUMBER(FIND(",",Товары_исходные!F103)),ISNUMBER(FIND(".",Товары_исходные!F103))),SUBSTITUTE(SUBSTITUTE(SUBSTITUTE(SUBSTITUTE(Товары_исходные!F103," ",""),"руб.",""),"руб",""),",",""),SUBSTITUTE(SUBSTITUTE(SUBSTITUTE(SUBSTITUTE(Товары_исходные!F103," ",""),"руб.",""),"руб",""),",","."))),0) -> 58500 | G103: =IFERROR(VLOOKUP(Товары_исходные!G103,Справочники!$D$2:$E$50,2,FALSE),"шт.") -> шт. | H103: =IF(F103>=E103,"OK","Розница ниже закупки") -> OK | I103: =IF(COUNTIF($A$2:$A$502,A103)=1,"OK","Дубликат") -> OK
A104: ="АРТ-"&LEFT(SUBSTITUTE(SUBSTITUTE(SUBSTITUTE(SUBSTITUTE(Товары_исходные!A104,"№",""),"АРТ-",""),"АРТ_",""),"/","-"),3) -> АРТ-103 | B104: =PROPER(TRIM(IFERROR(LEFT(Товары_исходные!B104,FIND("(",Товары_исходные!B104)-1),Товары_исходные!B104))) -> Ноутбук Msi Stealth 16 | C104: =IFERROR(VLOOKUP(Товары_исходные!C104,Справочники!$A$2:$B$50,2,FALSE),Товары_исходные!C104) -> Ноутбуки | D104: =PROPER(TRIM(Товары_исходные!D104)) -> Msi | E104: =IFERROR(VALUE(IF(AND(ISNUMBER(FIND(",",Товары_исходные!E104)),ISNUMBER(FIND(".",Товары_исходные!E104))),SUBSTITUTE(SUBSTITUTE(SUBSTITUTE(SUBSTITUTE(Товары_исходные!E104," ",""),"руб.",""),"руб",""),",",""),SUBSTITUTE(SUBSTITUTE(SUBSTITUTE(SUBSTITUTE(Товары_исходные!E104," ",""),"руб.",""),"руб",""),",","."))),0) -> 98000 | F104: =IFERROR(VALUE(IF(AND(ISNUMBER(FIND(",",Товары_исходные!F104)),ISNUMBER(FIND(".",Товары_исходные!F104))),SUBSTITUTE(SUBSTITUTE(SUBSTITUTE(SUBSTITUTE(Товары_исходные!F104," ",""),"руб.",""),"руб",""),",",""),SUBSTITUTE(SUBSTITUTE(SUBSTITUTE(SUBSTITUTE(Товары_исходные!F104," ",""),"руб.",""),"руб",""),",","."))),0) -> 149990 | G104: =IFERROR(VLOOKUP(Товары_исходные!G104,Справочники!$D$2:$E$50,2,FALSE),"шт.") -> шт. | H104: =IF(F104>=E104,"OK","Розница ниже закупки") -> OK | I104: =IF(COUNTIF($A$2:$A$502,A104)=1,"OK","Дубликат") -> OK
A105: ="АРТ-"&LEFT(SUBSTITUTE(SUBSTITUTE(SUBSTITUTE(SUBSTITUTE(Товары_исходные!A105,"№",""),"АРТ-",""),"АРТ_",""),"/","-"),3) -> АРТ-104 | B105: =PROPER(TRIM(IFERROR(LEFT(Товары_исходные!B105,FIND("(",Товары_исходные!B105)-1),Товары_исходные!B105))) -> Ноутбук Msi Stealth 16 | C105: =IFERROR(VLOOKUP(Товары_исходные!C105,Справочники!$A$2:$B$50,2,FALSE),Товары_исходные!C105) -> Ноутбуки | D105: =PROPER(TRIM(Товары_исходные!D105)) -> Msi | E105: =IFERROR(VALUE(IF(AND(ISNUMBER(FIND(",",Товары_исходные!E105)),ISNUMBER(FIND(".",Товары_исходные!E105))),SUBSTITUTE(SUBSTITUTE(SUBSTITUTE(SUBSTITUTE(Товары_исходные!E105," ",""),"руб.",""),"руб",""),",",""),SUBSTITUTE(SUBSTITUTE(SUBSTITUTE(SUBSTITUTE(Товары_исходные!E105," ",""),"руб.",""),"руб",""),",","."))),0) -> 96000 | F105: =IFERROR(VALUE(IF(AND(ISNUMBER(FIND(",",Товары_исходные!F105)),ISNUMBER(FIND(".",Товары_исходные!F105))),SUBSTITUTE(SUBSTITUTE(SUBSTITUTE(SUBSTITUTE(Товары_исходные!F105," ",""),"руб.",""),"руб",""),",",""),SUBSTITUTE(SUBSTITUTE(SUBSTITUTE(SUBSTITUTE(Товары_исходные!F105," ",""),"руб.",""),"руб",""),",","."))),0) -> 147000 | G105: =IFERROR(VLOOKUP(Товары_исходные!G105,Справочники!$D$2:$E$50,2,FALSE),"шт.") -> шт. | H105: =IF(F105>=E105,"OK","Розница ниже закупки") -> OK | I105: =IF(COUNTIF($A$2:$A$502,A105)=1,"OK","Дубликат") -> OK
A106: ="АРТ-"&LEFT(SUBSTITUTE(SUBSTITUTE(SUBSTITUTE(SUBSTITUTE(Товары_исходные!A106,"№",""),"АРТ-",""),"АРТ_",""),"/","-"),3) -> АРТ-105 | B106: =PROPER(TRIM(IFERROR(LEFT(Товары_исходные!B106,FIND("(",Товары_исходные!B106)-1),Товары_исходные!B106))) -> Ноутбук Msi Stealth 16 | C106: =IFERROR(VLOOKUP(Товары_исходные!C106,Справочники!$A$2:$B$50,2,FALSE),Товары_исходные!C106) -> Ноутбуки | D106: =PROPER(TRIM(Товары_исходные!D106)) -> Msi | E106: =IFERROR(VALUE(IF(AND(ISNUMBER(FIND(",",Товары_исходные!E106)),ISNUMBER(FIND(".",Товары_исходные!E106))),SUBSTITUTE(SUBSTITUTE(SUBSTITUTE(SUBSTITUTE(Товары_исходные!E106," ",""),"руб.",""),"руб",""),",",""),SUBSTITUTE(SUBSTITUTE(SUBSTITUTE(SUBSTITUTE(Товары_исходные!E106," ",""),"руб.",""),"руб",""),",","."))),0) -> 99500 | F106: =IFERROR(VALUE(IF(AND(ISNUMBER(FIND(",",Товары_исходные!F106)),ISNUMBER(FIND(".",Товары_исходные!F106))),SUBSTITUTE(SUBSTITUTE(SUBSTITUTE(SUBSTITUTE(Товары_исходные!F106," ",""),"руб.",""),"руб",""),",",""),SUBSTITUTE(SUBSTITUTE(SUBSTITUTE(SUBSTITUTE(Товары_исходные!F106," ",""),"руб.",""),"руб",""),",","."))),0) -> 152000 | G106: =IFERROR(VLOOKUP(Товары_исходные!G106,Справочники!$D$2:$E$50,2,FALSE),"шт.") -> шт. | H106: =IF(F106>=E106,"OK","Розница ниже закупки") -> OK | I106: =IF(COUNTIF($A$2:$A$502,A106)=1,"OK","Дубликат") -> OK
A107: ="АРТ-"&LEFT(SUBSTITUTE(SUBSTITUTE(SUBSTITUTE(SUBSTITUTE(Товары_исходные!A107,"№",""),"АРТ-",""),"АРТ_",""),"/","-"),3) -> АРТ-106 | B107: =PROPER(TRIM(IFERROR(LEFT(Товары_исходные!B107,FIND("(",Товары_исходные!B107)-1),Товары_исходные!B107))) -> Смартфон Realme Gt 3 | C107: =IFERROR(VLOOKUP(Товары_исходные!C107,Справочники!$A$2:$B$50,2,FALSE),Товары_исходные!C107) -> Смартфоны | D107: =PROPER(TRIM(Товары_исходные!D107)) -> Realme | E107: =IFERROR(VALUE(IF(AND(ISNUMBER(FIND(",",Товары_исходные!E107)),ISNUMBER(FIND(".",Товары_исходные!E107))),SUBSTITUTE(SUBSTITUTE(SUBSTITUTE(SUBSTITUTE(Товары_исходные!E107," ",""),"руб.",""),"руб",""),",",""),SUBSTITUTE(SUBSTITUTE(SUBSTITUTE(SUBSTITUTE(Товары_исходные!E107," ",""),"руб.",""),"руб",""),",","."))),0) -> 28000 | F107: =IFERROR(VALUE(IF(AND(ISNUMBER(FIND(",",Товары_исходные!F107)),ISNUMBER(FIND(".",Товары_исходные!F107))),SUBSTITUTE(SUBSTITUTE(SUBSTITUTE(SUBSTITUTE(Товары_исходные!F107," ",""),"руб.",""),"руб",""),",",""),SUBSTITUTE(SUBSTITUTE(SUBSTITUTE(SUBSTITUTE(Товары_исходные!F107," ",""),"руб.",""),"руб",""),",","."))),0) -> 47990 | G107: =IFERROR(VLOOKUP(Товары_исходные!G107,Справочники!$D$2:$E$50,2,FALSE),"шт.") -> шт. | H107: =IF(F107>=E107,"OK","Розница ниже закупки") -> OK | I107: =IF(COUNTIF($A$2:$A$502,A107)=1,"OK","Дубликат") -> OK
A108: ="АРТ-"&LEFT(SUBSTITUTE(SUBSTITUTE(SUBSTITUTE(SUBSTITUTE(Товары_исходные!A108,"№",""),"АРТ-",""),"АРТ_",""),"/","-"),3) -> АРТ-107 | B108: =PROPER(TRIM(IFERROR(LEFT(Товары_исходные!B108,FIND("(",Товары_исходные!B108)-1),Товары_исходные!B108))) -> Смартфон Realme Gt 3 | C108: =IFERROR(VLOOKUP(Товары_исходные!C108,Справочники!$A$2:$B$50,2,FALSE),Товары_исходные!C108) -> Смартфоны | D108: =PROPER(TRIM(Товары_исходные!D108)) -> Realme | E108: =IFERROR(VALUE(IF(AND(ISNUMBER(FIND(",",Товары_исходные!E108)),ISNUMBER(FIND(".",Товары_исходные!E108))),SUBSTITUTE(SUBSTITUTE(SUBSTITUTE(SUBSTITUTE(Товары_исходные!E108," ",""),"руб.",""),"руб",""),",",""),SUBSTITUTE(SUBSTITUTE(SUBSTITUTE(SUBSTITUTE(Товары_исходные!E108," ",""),"руб.",""),"руб",""),",","."))),0) -> 27000 | F108: =IFERROR(VALUE(IF(AND(ISNUMBER(FIND(",",Товары_исходные!F108)),ISNUMBER(FIND(".",Товары_исходные!F108))),SUBSTITUTE(SUBSTITUTE(SUBSTITUTE(SUBSTITUTE(Товары_исходные!F108," ",""),"руб.",""),"руб",""),",",""),SUBSTITUTE(SUBSTITUTE(SUBSTITUTE(SUBSTITUTE(Товары_исходные!F108," ",""),"руб.",""),"руб",""),",","."))),0) -> 46500 | G108: =IFERROR(VLOOKUP(Товары_исходные!G108,Справочники!$D$2:$E$50,2,FALSE),"шт.") -> шт. | H108: =IF(F108>=E108,"OK","Розница ниже закупки") -> OK | I108: =IF(COUNTIF($A$2:$A$502,A108)=1,"OK","Дубликат") -> OK
A109: ="АРТ-"&LEFT(SUBSTITUTE(SUBSTITUTE(SUBSTITUTE(SUBSTITUTE(Товары_исходные!A109,"№",""),"АРТ-",""),"АРТ_",""),"/","-"),3) -> АРТ-108 | B109: =PROPER(TRIM(IFERROR(LEFT(Товары_исходные!B109,FIND("(",Товары_исходные!B109)-1),Товары_исходные!B109))) -> Смартфон Realme Gt 3 | C109: =IFERROR(VLOOKUP(Товары_исходные!C109,Справочники!$A$2:$B$50,2,FALSE),Товары_исходные!C109) -> Смартфоны | D109: =PROPER(TRIM(Товары_исходные!D109)) -> Realme | E109: =IFERROR(VALUE(IF(AND(ISNUMBER(FIND(",",Товары_исходные!E109)),ISNUMBER(FIND(".",Товары_исходные!E109))),SUBSTITUTE(SUBSTITUTE(SUBSTITUTE(SUBSTITUTE(Товары_исходные!E109," ",""),"руб.",""),"руб",""),",",""),SUBSTITUTE(SUBSTITUTE(SUBSTITUTE(SUBSTITUTE(Товары_исходные!E109," ",""),"руб.",""),"руб",""),",","."))),0) -> 29000 | F109: =IFERROR(VALUE(IF(AND(ISNUMBER(FIND(",",Товары_исходные!F109)),ISNUMBER(FIND(".",Товары_исходные!F109))),SUBSTITUTE(SUBSTITUTE(SUBSTITUTE(SUBSTITUTE(Товары_исходные!F109," ",""),"руб.",""),"руб",""),",",""),SUBSTITUTE(SUBSTITUTE(SUBSTITUTE(SUBSTITUTE(Товары_исходные!F109," ",""),"руб.",""),"руб",""),",","."))),0) -> 49500 | G109: =IFERROR(VLOOKUP(Товары_исходные!G109,Справочники!$D$2:$E$50,2,FALSE),"шт.") -> шт. | H109: =IF(F109>=E109,"OK","Розница ниже закупки") -> OK | I109: =IF(COUNTIF($A$2:$A$502,A109)=1,"OK","Дубликат") -> OK
A110: ="АРТ-"&LEFT(SUBSTITUTE(SUBSTITUTE(SUBSTITUTE(SUBSTITUTE(Товары_исходные!A110,"№",""),"АРТ-",""),"АРТ_",""),"/","-"),3) -> АРТ-109 | B110: =PROPER(TRIM(IFERROR(LEFT(Товары_исходные!B110,FIND("(",Товары_исходные!B110)-1),Товары_исходные!B110))) -> Телевизор Hisense U8K | C110: =IFERROR(VLOOKUP(Товары_исходные!C110,Справочники!$A$2:$B$50,2,FALSE),Товары_исходные!C110) -> Телевизоры | D110: =PROPER(TRIM(Товары_исходные!D110)) -> Hisense | E110: =IFERROR(VALUE(IF(AND(ISNUMBER(FIND(",",Товары_исходные!E110)),ISNUMBER(FIND(".",Товары_исходные!E110))),SUBSTITUTE(SUBSTITUTE(SUBSTITUTE(SUBSTITUTE(Товары_исходные!E110," ",""),"руб.",""),"руб",""),",",""),SUBSTITUTE(SUBSTITUTE(SUBSTITUTE(SUBSTITUTE(Товары_исходные!E110," ",""),"руб.",""),"руб",""),",","."))),0) -> 78000 | F110: =IFERROR(VALUE(IF(AND(ISNUMBER(FIND(",",Товары_исходные!F110)),ISNUMBER(FIND(".",Товары_исходные!F110))),SUBSTITUTE(SUBSTITUTE(SUBSTITUTE(SUBSTITUTE(Товары_исходные!F110," ",""),"руб.",""),"руб",""),",",""),SUBSTITUTE(SUBSTITUTE(SUBSTITUTE(SUBSTITUTE(Товары_исходные!F110," ",""),"руб.",""),"руб",""),",","."))),0) -> 119999 | G110: =IFERROR(VLOOKUP(Товары_исходные!G110,Справочники!$D$2:$E$50,2,FALSE),"шт.") -> шт. | H110: =IF(F110>=E110,"OK","Розница ниже закупки") -> OK | I110: =IF(COUNTIF($A$2:$A$502,A110)=1,"OK","Дубликат") -> OK
A111: ="АРТ-"&LEFT(SUBSTITUTE(SUBSTITUTE(SUBSTITUTE(SUBSTITUTE(Товары_исходные!A111,"№",""),"АРТ-",""),"АРТ_",""),"/","-"),3) -> АРТ-110 | B111: =PROPER(TRIM(IFERROR(LEFT(Товары_исходные!B111,FIND("(",Товары_исходные!B111)-1),Товары_исходные!B111))) -> Телевизор Hisense U8K | C111: =IFERROR(VLOOKUP(Товары_исходные!C111,Справочники!$A$2:$B$50,2,FALSE),Товары_исходные!C111) -> Телевизоры | D111: =PROPER(TRIM(Товары_исходные!D111)) -> Hisense | E111: =IFERROR(VALUE(IF(AND(ISNUMBER(FIND(",",Товары_исходные!E111)),ISNUMBER(FIND(".",Товары_исходные!E111))),SUBSTITUTE(SUBSTITUTE(SUBSTITUTE(SUBSTITUTE(Товары_исходные!E111," ",""),"руб.",""),"руб",""),",",""),SUBSTITUTE(SUBSTITUTE(SUBSTITUTE(SUBSTITUTE(Товары_исходные!E111," ",""),"руб.",""),"руб",""),",","."))),0) -> 76000 | F111: =IFERROR(VALUE(IF(AND(ISNUMBER(FIND(",",Товары_исходные!F111)),ISNUMBER(FIND(".",Товары_исходные!F111))),SUBSTITUTE(SUBSTITUTE(SUBSTITUTE(SUBSTITUTE(Товары_исходные!F111," ",""),"руб.",""),"руб",""),",",""),SUBSTITUTE(SUBSTITUTE(SUBSTITUTE(SUBSTITUTE(Товары_исходные!F111," ",""),"руб.",""),"руб",""),",","."))),0) -> 117000 | G111: =IFERROR(VLOOKUP(Товары_исходные!G111,Справочники!$D$2:$E$50,2,FALSE),"шт.") -> шт. | H111: =IF(F111>=E111,"OK","Розница ниже закупки") -> OK | I111: =IF(COUNTIF($A$2:$A$502,A111)=1,"OK","Дубликат") -> OK
A112: ="АРТ-"&LEFT(SUBSTITUTE(SUBSTITUTE(SUBSTITUTE(SUBSTITUTE(Товары_исходные!A112,"№",""),"АРТ-",""),"АРТ_",""),"/","-"),3) -> АРТ-111 | B112: =PROPER(TRIM(IFERROR(LEFT(Товары_исходные!B112,FIND("(",Товары_исходные!B112)-1),Товары_исходные!B112))) -> Телевизор Hisense U8K | C112: =IFERROR(VLOOKUP(Товары_исходные!C112,Справочники!$A$2:$B$50,2,FALSE),Товары_исходные!C112) -> Телевизоры | D112: =PROPER(TRIM(Товары_исходные!D112)) -> Hisense | E112: =IFERROR(VALUE(IF(AND(ISNUMBER(FIND(",",Товары_исходные!E112)),ISNUMBER(FIND(".",Товары_исходные!E112))),SUBSTITUTE(SUBSTITUTE(SUBSTITUTE(SUBSTITUTE(Товары_исходные!E112," ",""),"руб.",""),"руб",""),",",""),SUBSTITUTE(SUBSTITUTE(SUBSTITUTE(SUBSTITUTE(Товары_исходные!E112," ",""),"руб.",""),"руб",""),",","."))),0) -> 79500 | F112: =IFERROR(VALUE(IF(AND(ISNUMBER(FIND(",",Товары_исходные!F112)),ISNUMBER(FIND(".",Товары_исходные!F112))),SUBSTITUTE(SUBSTITUTE(SUBSTITUTE(SUBSTITUTE(Товары_исходные!F112," ",""),"руб.",""),"руб",""),",",""),SUBSTITUTE(SUBSTITUTE(SUBSTITUTE(SUBSTITUTE(Товары_исходные!F112," ",""),"руб.",""),"руб",""),",","."))),0) -> 122500 | G112: =IFERROR(VLOOKUP(Товары_исходные!G112,Справочники!$D$2:$E$50,2,FALSE),"шт.") -> шт. | H112: =IF(F112>=E112,"OK","Розница ниже закупки") -> OK | I112: =IF(COUNTIF($A$2:$A$502,A112)=1,"OK","Дубликат") -> OK
... A502: ="АРТ-"&LEFT(SUBSTITUTE(SUBSTITUTE(SUBSTITUTE(SUBSTITUTE(Товары_исходные!A502,"№",""),"АРТ-",""),"АРТ_",""),"/","-"),3) -> АРТ-501 | B502: =PROPER(TRIM(IFERROR(LEFT(Товары_исходные!B502,FIND("(",Товары_исходные!B502)-1),Товары_исходные!B502))) -> Клавиатура Logitech Pop Keys | C502: =IFERROR(VLOOKUP(Товары_исходные!C502,Справочники!$A$2:$B$50,2,FALSE),Товары_исходные!C502) -> Аксессуары | D502: =PROPER(TRIM(Товары_исходные!D502)) -> Logitech | E502: =IFERROR(VALUE(IF(AND(ISNUMBER(FIND(",",Товары_исходные!E502)),ISNUMBER(FIND(".",Товары_исходные!E502))),SUBSTITUTE(SUBSTITUTE(SUBSTITUTE(SUBSTITUTE(Товары_исходные!E502," ",""),"руб.",""),"руб",""),",",""),SUBSTITUTE(SUBSTITUTE(SUBSTITUTE(SUBSTITUTE(Товары_исходные!E502," ",""),"руб.",""),"руб",""),",","."))),0) -> 4000 | F502: =IFERROR(VALUE(IF(AND(ISNUMBER(FIND(",",Товары_исходные!F502)),ISNUMBER(FIND(".",Товары_исходные!F502))),SUBSTITUTE(SUBSTITUTE(SUBSTITUTE(SUBSTITUTE(Товары_исходные!F502," ",""),"руб.",""),"руб",""),",",""),SUBSTITUTE(SUBSTITUTE(SUBSTITUTE(SUBSTITUTE(Товары_исходные!F502," ",""),"руб.",""),"руб",""),",","."))),0) -> 6800 | G502: =IFERROR(VLOOKUP(Товары_исходные!G502,Справочники!$D$2:$E$50,2,FALSE),"шт.") -> шт. | H502: =IF(F502>=E502,"OK","Розница ниже закупки") -> OK | I502: =IF(COUNTIF($A$2:$A$502,A502)=1,"OK","Дубликат") -> OK

Sheet Поставщики_исходные
A1: ID_поставщика | B1: Название | C1: ИНН | D1: КПП | E1: Телефон | F1: Email | G1: Адрес
A2: P001 | B2: ООО ТехноСнаб | C2: 7708123456 | D2: 770801001 | E2: 8-903-123-45-67 | F2: info@tehnosnab.ru | G2: 125009 г.Москва ул.Тверская д.15
A3: P002 | B3: ЗАО ЭлектроПром | C3: 7812345678123 | D3: 781201001 | E3: +7 903 234-56-78 | F3: zakaz@electroprom | G3: 191186 г.Санкт-Петербург Невский пр.д.28
A4: P003 | B4: ООО КомплектСервис | C4: 77098765 | D4: 770901001 | E4: 8 903 345 67 89 | F4: komplekt@mail.ru | G4: 127006 г.Москва ул.Петровка д.20
A5: P004 | B5: АО ТехноИмпорт | C5: 7712345678 | D5: 771001001 | E5: +79034567890 | F5: import@techno | G5: 119019 г.Москва ул.Арбат д.12
A6: P005 | B6: ООО ТоргМастер | C6: 7801234567890 | D6: 780101001 | E6: 8-903-567-89-01 | F6: torg@master | G6: 192007 г.Санкт-Петербург пр.Обуховской Обороны д.120
A7: P006 | B7: ЗАО Техноресурс | C7: 77134567 | D7: 771101001 | E7: 8-903-678-90-12 | F7: resurs@techno.ru | G7: 119121 г.Москва ул.Плющиха д.25
A8: P007 | B8: ООО ПрогрессПлюс | C8: 7802345678 | D8: 780201001 | E8: +7 903 789-01-23 | F8: progress@mail | G8: 197022 г.Санкт-Петербург ул.Профессора Попова д.37
A9: P008 | B9: АО ЭлектронСбыт | C9: 771456789012 | D9: 771201001 | E9: 8-903-890-12-34 | F9: electron@sbyt | G9: 109316 г.Москва ул.Таганская д.54
A10: P009 | B10: ООО СмартТех | C10: 7803456789 | D10: 780301001 | E10: +79039012345 | F10: smart@tech | G10: 196084 г.Санкт-Петербург ул.Заставская д.22
A11: P010 | B11: ЗАО ТехноПром | C11: 7715678901 | D11: 771301001 | E11: 8-903-012-34-56 | F11: prom@tehno | G11: 119334 г.Москва ул.Косыгина д.17
A12: P011 | B12: ООО СервисПлюс | C12: 78045678 | D12: 780401001 | E12: 8-903-123-45-67 | F12: service@plus.ru | G12: 199178 г.Санкт-Петербург ул.Средний пр.В.О.д.78
... A51: P050 | B51: ЗАО ТехноПроект | C51: 7735678901 | D51: 773301001 | E51: 8-903-012-34-56 | F51: proekt@tehno | G51: 119435 г.Москва ул.Погодинская д.18

Sheet Поставщики_очищенные
A1: ID_поставщика | B1: Название | C1: ИНН | D1: КПП | E1: Телефон | F1: Email | G1: Адрес | H1: Индекс | I1: Адрес_остаток | J1: Проверка_ИНН | K1: Проверка_Email
A2: ='Поставщики_исходные'!A2 -> P001 | B2: =PROPER(TRIM('Поставщики_исходные'!B2)) -> Ооо Техноснаб | C2: =IF(ISBLANK(Поставщики_исходные!C2),"",TRIM(Поставщики_исходные!C2)) -> 7708123456 | D2: ='Поставщики_исходные'!D2 -> 770801001 | E2: =IF(ISBLANK(Поставщики_исходные!E2),"",IF(LEN(SUBSTITUTE(SUBSTITUTE(SUBSTITUTE(SUBSTITUTE(SUBSTITUTE(Поставщики_исходные!E2," ",""),"-",""),"+",""),"(",""),")",""))=11,"+7 ("&MID(IF(LEFT(SUBSTITUTE(SUBSTITUTE(SUBSTITUTE(SUBSTITUTE(SUBSTITUTE(Поставщики_исходные!E2," ",""),"-",""),"+",""),"(",""),")",""))="8","7"&MID(SUBSTITUTE(SUBSTITUTE(SUBSTITUTE(SUBSTITUTE(SUBSTITUTE(Поставщики_исходные!E2," ",""),"-",""),"+",""),"(",""),")",""),2,10),SUBSTITUTE(SUBSTITUTE(SUBSTITUTE(SUBSTITUTE(SUBSTITUTE(Поставщики_исходные!E2," ",""),"-",""),"+",""),"(",""),")","")),2,3)&") "&MID(IF(LEFT(SUBSTITUTE(SUBSTITUTE(SUBSTITUTE(SUBSTITUTE(SUBSTITUTE(Поставщики_исходные!E2," ",""),"-",""),"+",""),"(",""),")",""))="8","7"&MID(SUBSTITUTE(SUBSTITUTE(SUBSTITUTE(SUBSTITUTE(SUBSTITUTE(Поставщики_исходные!E2," ",""),"-",""),"+",""),"(",""),")",""),2,10),SUBSTITUTE(SUBSTITUTE(SUBSTITUTE(SUBSTITUTE(SUBSTITUTE(Поставщики_исходные!E2," ",""),"-",""),"+",""),"(",""),")","")),5,3)&"-"&MID(IF(LEFT(SUBSTITUTE(SUBSTITUTE(SUBSTITUTE(SUBSTITUTE(SUBSTITUTE(Поставщики_исходные!E2," ",""),"-",""),"+",""),"(",""),")",""))="8","7"&MID(SUBSTITUTE(SUBSTITUTE(SUBSTITUTE(SUBSTITUTE(SUBSTITUTE(Поставщики_исходные!E2," ",""),"-",""),"+",""),"(",""),")",""),2,10),SUBSTITUTE(SUBSTITUTE(SUBSTITUTE(SUBSTITUTE(SUBSTITUTE(Поставщики_исходные!E2," ",""),"-",""),"+",""),"(",""),")","")),8,2)&"-"&MID(IF(LEFT(SUBSTITUTE(SUBSTITUTE(SUBSTITUTE(SUBSTITUTE(SUBSTITUTE(Поставщики_исходные!E2," ",""),"-",""),"+",""),"(",""),")",""))="8","7"&MID(SUBSTITUTE(SUBSTITUTE(SUBSTITUTE(SUBSTITUTE(SUBSTITUTE(Поставщики_исходные!E2," ",""),"-",""),"+",""),"(",""),")",""),2,10),SUBSTITUTE(SUBSTITUTE(SUBSTITUTE(SUBSTITUTE(SUBSTITUTE(Поставщики_исходные!E2," ",""),"-",""),"+",""),"(",""),")","")),10,2),IF(LEN(SUBSTITUTE(SUBSTITUTE(SUBSTITUTE(SUBSTITUTE(SUBSTITUTE(Поставщики_исходные!E2," ",""),"-",""),"+",""),"(",""),")",""))=10,"+7 ("&MID(SUBSTITUTE(SUBSTITUTE(SUBSTITUTE(SUBSTITUTE(SUBSTITUTE(Поставщики_исходные!E2," ",""),"-",""),"+",""),"(",""),")",""),1,3)&") "&MID(SUBSTITUTE(SUBSTITUTE(SUBSTITUTE(SUBSTITUTE(SUBSTITUTE(Поставщики_исходные!E2," ",""),"-",""),"+",""),"(",""),")",""),4,3)&"-"&MID(SUBSTITUTE(SUBSTITUTE(SUBSTITUTE(SUBSTITUTE(SUBSTITUTE(Поставщики_исходные!E2," ",""),"-",""),"+",""),"(",""),")",""),6,2)&"-"&MID(SUBSTITUTE(SUBSTITUTE(SUBSTITUTE(SUBSTITUTE(SUBSTITUTE(Поставщики_исходные!E2," ",""),"-",""),"+",""),"(",""),")",""),8,2),Поставщики_исходные!E2))) -> +7 (903) 123-45-67 | F2: =IF(ISBLANK(Поставщики_исходные!F2),"",IF(ISNUMBER(FIND(".",MID(Поставщики_исходные!F2,FIND("@",Поставщики_исходные!F2)+1,255))),Поставщики_исходные!F2,IF(ISNUMBER(FIND("gmail",Поставщики_исходные!F2)),Поставщики_исходные!F2&".com",Поставщики_исходные!F2&".ru"))) -> info@tehnosnab.ru | G2: =TRIM('Поставщики_исходные'!G2) -> 125009 г.Москва ул.Тверская д.15 | H2: =IF(ISNUMBER(VALUE(LEFT(TRIM('Поставщики_исходные'!G2),6))),LEFT(TRIM('Поставщики_исходные'!G2),6),"") -> 125009 | I2: =TRIM(MID(TRIM('Поставщики_исходные'!G2),7,255)) -> г.Москва ул.Тверская д.15 | J2: =IF(OR(LEN(C2)=10,LEN(C2)=12),"OK","Ошибка ИНН") -> OK | K2: =IF(ISBLANK(Поставщики_исходные!F2),"",IF(ISNUMBER(FIND(".",MID(Поставщики_исходные!F2,FIND("@",Поставщики_исходные!F2)+1,255))),Поставщики_исходные!F2,IF(ISNUMBER(FIND("gmail",Поставщики_исходные!F2)),Поставщики_исходные!F2&".com",Поставщики_исходные!F2&".ru"))) -> info@tehnosnab.ru
A3: =Поставщики_исходные!A3 -> P002 | B3: =PROPER(TRIM(Поставщики_исходные!B3)) -> Зао Электропром | C3: =IF(ISBLANK(Поставщики_исходные!C3),"",TRIM(Поставщики_исходные!C3)) -> 7812345678123 | D3: =Поставщики_исходные!D3 -> 781201001 | E3: =IF(ISBLANK(Поставщики_исходные!E3),"",IF(LEN(SUBSTITUTE(SUBSTITUTE(SUBSTITUTE(SUBSTITUTE(SUBSTITUTE(Поставщики_исходные!E3," ",""),"-",""),"+",""),"(",""),")",""))=11,"+7 ("&MID(IF(LEFT(SUBSTITUTE(SUBSTITUTE(SUBSTITUTE(SUBSTITUTE(SUBSTITUTE(Поставщики_исходные!E3," ",""),"-",""),"+",""),"(",""),")",""))="8","7"&MID(SUBSTITUTE(SUBSTITUTE(SUBSTITUTE(SUBSTITUTE(SUBSTITUTE(Поставщики_исходные!E3," ",""),"-",""),"+",""),"(",""),")",""),2,10),SUBSTITUTE(SUBSTITUTE(SUBSTITUTE(SUBSTITUTE(SUBSTITUTE(Поставщики_исходные!E3," ",""),"-",""),"+",""),"(",""),")","")),2,3)&") "&MID(IF(LEFT(SUBSTITUTE(SUBSTITUTE(SUBSTITUTE(SUBSTITUTE(SUBSTITUTE(Поставщики_исходные!E3," ",""),"-",""),"+",""),"(",""),")",""))="8","7"&MID(SUBSTITUTE(SUBSTITUTE(SUBSTITUTE(SUBSTITUTE(SUBSTITUTE(Поставщики_исходные!E3," ",""),"-",""),"+",""),"(",""),")",""),2,10),SUBSTITUTE(SUBSTITUTE(SUBSTITUTE(SUBSTITUTE(SUBSTITUTE(Поставщики_исходные!E3," ",""),"-",""),"+",""),"(",""),")","")),5,3)&"-"&MID(IF(LEFT(SUBSTITUTE(SUBSTITUTE(SUBSTITUTE(SUBSTITUTE(SUBSTITUTE(Поставщики_исходные!E3," ",""),"-",""),"+",""),"(",""),")",""))="8","7"&MID(SUBSTITUTE(SUBSTITUTE(SUBSTITUTE(SUBSTITUTE(SUBSTITUTE(Поставщики_исходные!E3," ",""),"-",""),"+",""),"(",""),")",""),2,10),SUBSTITUTE(SUBSTITUTE(SUBSTITUTE(SUBSTITUTE(SUBSTITUTE(Поставщики_исходные!E3," ",""),"-",""),"+",""),"(",""),")","")),8,2)&"-"&MID(IF(LEFT(SUBSTITUTE(SUBSTITUTE(SUBSTITUTE(SUBSTITUTE(SUBSTITUTE(Поставщики_исходные!E3," ",""),"-",""),"+",""),"(",""),")",""))="8","7"&MID(SUBSTITUTE(SUBSTITUTE(SUBSTITUTE(SUBSTITUTE(SUBSTITUTE(Поставщики_исходные!E3," ",""),"-",""),"+",""),"(",""),")",""),2,10),SUBSTITUTE(SUBSTITUTE(SUBSTITUTE(SUBSTITUTE(SUBSTITUTE(Поставщики_исходные!E3," ",""),"-",""),"+",""),"(",""),")","")),10,2),IF(LEN(SUBSTITUTE(SUBSTITUTE(SUBSTITUTE(SUBSTITUTE(SUBSTITUTE(Поставщики_исходные!E3," ",""),"-",""),"+",""),"(",""),")",""))=10,"+7 ("&MID(SUBSTITUTE(SUBSTITUTE(SUBSTITUTE(SUBSTITUTE(SUBSTITUTE(Поставщики_исходные!E3," ",""),"-",""),"+",""),"(",""),")",""),1,3)&") "&MID(SUBSTITUTE(SUBSTITUTE(SUBSTITUTE(SUBSTITUTE(SUBSTITUTE(Поставщики_исходные!E3," ",""),"-",""),"+",""),"(",""),")",""),4,3)&"-"&MID(SUBSTITUTE(SUBSTITUTE(SUBSTITUTE(SUBSTITUTE(SUBSTITUTE(Поставщики_исходные!E3," ",""),"-",""),"+",""),"(",""),")",""),6,2)&"-"&MID(SUBSTITUTE(SUBSTITUTE(SUBSTITUTE(SUBSTITUTE(SUBSTITUTE(Поставщики_исходные!E3," ",""),"-",""),"+",""),"(",""),")",""),8,2),Поставщики_исходные!E3))) -> +7 (903) 234-56-78 | F3: =IF(ISBLANK(Поставщики_исходные!F3),"",IF(ISNUMBER(FIND(".",MID(Поставщики_исходные!F3,FIND("@",Поставщики_исходные!F3)+1,255))),Поставщики_исходные!F3,IF(ISNUMBER(FIND("gmail",Поставщики_исходные!F3)),Поставщики_исходные!F3&".com",Поставщики_исходные!F3&".ru"))) -> zakaz@electroprom.ru | G3: =TRIM(Поставщики_исходные!G3) -> 191186 г.Санкт-Петербург Невский пр.д.28 | H3: =IF(ISNUMBER(VALUE(LEFT(TRIM(Поставщики_исходные!G3),6))),LEFT(TRIM(Поставщики_исходные!G3),6),"") -> 191186 | I3: =TRIM(MID(TRIM(Поставщики_исходные!G3),7,255)) -> г.Санкт-Петербург Невский пр.д.28 | J3: =IF(OR(LEN(C3)=10,LEN(C3)=12),"OK","Ошибка ИНН") -> Ошибка ИНН | K3: =IF(AND(ISNUMBER(FIND("@",F3)),ISNUMBER(FIND(".",MID(F3,FIND("@",F3)+1,255)))),"OK","Ошибка Email") -> OK
